<?xml version="1.0" ?>
<!-- =================================================================================== -->
<!-- |    This document was autogenerated by xacro from differential_drive.xacro       | -->
<!-- |    EDITING THIS FILE BY HAND IS NOT RECOMMENDED                                 | -->
<!-- =================================================================================== -->
<!--Defining Robot-->
<robot name="differential_drive" xmlns:xacro="http://www.ros.org/wiki/xacro">
  <!--Defining Materials-->
  <!--Defining Black Material-->
  <material name="Black">
    <color rgba="0 0 0 1"/>
  </material>
  <!--Defining White Material-->
  <material name="White">
    <color rgba="1 1 1 1"/>
  </material>
  <!--Defining Red Material-->
  <material name="Red">
    <color rgba="0.8 0 0 1"/>
  </material>
  <!--Defining Blue Material-->
  <material name="Blue">
    <color rgba="0 0 0.8 1"/>
  </material>
  <!--Mass in kg-->
  <!--weight in kg-->
  <!--Mass in kg-->
  <!--////////////////////////////////// Defining Base Footprint /////////////////////////////////-->
  <!--Base footprint is a friction less frame right below the base link origin-->
  <link name="base_footprint">
    <!--Defining Visual Property-->
    <visual>
      <geometry>
        <box size="0.001 0.001 0.001"/>
      </geometry>
      <!--origin-->
      <origin rpy="0 0 0" xyz="0 0 0"/>
    </visual>
    <!--Defining inertia-->
    <inertial>
      <mass value="0.0001"/>
      <inertia ixx="0.0001" ixy="0" ixz="0" iyy="0.0001" iyz="0" izz="0.0001"/>
    </inertial>
  </link>
  <!--Defininfg Joint-->
  <joint name="base_footprint_joint" type="fixed">
    <!--Parent link-->
    <parent link="base_footprint"/>
    <!--Child Link-->
    <child link="base_link"/>
    <!--origin-->
    <origin rpy="0 0 0" xyz="0 0 0.04"/>
  </joint>
  <!--////////////////////////////////// Defining Base Link /////////////////////////////////-->
  <link name="base_link">
    <!--Defining Visual Properties-->
    <visual>
      <geometry>
        <cylinder length="0.02" radius="0.15"/>
      </geometry>
      <!--Defining Origin-->
      <origin rpy="0 0 0" xyz="0 0 0"/>
      <!--Defining Material-->
      <material name="White"/>
    </visual>
    <!--Collision Property-->
    <collision>
      <geometry>
        <cylinder length="0.02" radius="0.15"/>
      </geometry>
      <!--Defining Origin-->
      <origin rpy="0 0 0" xyz="0 0 0"/>
    </collision>
    <interial>
      <mass value="5"/>
      <inertia ixx="0.0282916666667" ixy="0" ixz="0" iyy="0.0282916666667" iyz="0" izz="0.05625"/>
    </interial>
  </link>
  <!--Defining Link-->
  <link name="caster_front">
    <!--Defining Visual Properties-->
    <visual>
      <geometry>
        <sphere radius="0.025"/>
      </geometry>
      <!--Defining Origin-->
      <origin rpy="1.57079632679 0 0" xyz="0 0.02 0"/>
      <!--Defining Material-->
      <material name="Black"/>
    </visual>
    <!--Defining Collision-->
    <collision>
      <geometry>
        <sphere radius="0.025"/>
      </geometry>
      <!--Defining Origin-->
      <origin rpy="1.570796327 0 0" xyz="0 0.02 0"/>
    </collision>
    <inertial>
      <mass value="0.5"/>
      <!--INertia Matrix-->
      <inertia ixx="0.001" ixy="0" ixz="0" iyy="0.001" iyz="0" izz="0.001"/>
    </inertial>
  </link>
  <!--Defining Joint-->
  <joint name="caster_front_joint" type="fixed">
    <!--Defining Parent Link-->
    <parent link="base_link"/>
    <!--Defining Child Link-->
    <child link="caster_front"/>
    <!--Defining Origin-->
    <origin rpy="-1.57079632679 0 0" xyz="0.115 0.0 0.007"/>
  </joint>
  <!--Defining Link-->
  <link name="caster_back">
    <!--Defining Visual Properties-->
    <visual>
      <geometry>
        <sphere radius="0.025"/>
      </geometry>
      <!--Defining Origin-->
      <origin rpy="1.57079632679 0 0" xyz="0.02 0.02 0"/>
      <!--Defining Material-->
      <material name="Black"/>
    </visual>
    <!--Defining Collision-->
    <collision>
      <geometry>
        <sphere radius="0.025"/>
      </geometry>
      <!--Defining Origin-->
      <origin rpy="1.570796327 0 0" xyz="0.02 0.02 0"/>
    </collision>
    <inertial>
      <mass value="0.5"/>
      <!--INertia Matrix-->
      <inertia ixx="0.001" ixy="0" ixz="0" iyy="0.001" iyz="0" izz="0.001"/>
    </inertial>
  </link>
  <!--Defining Joint-->
  <joint name="caster_back_joint" type="fixed">
    <!--Defining Parent Link-->
    <parent link="base_link"/>
    <!--Defining Child Link-->
    <child link="caster_back"/>
    <!--Defining Origin-->
    <origin rpy="-1.57079632679 0 0" xyz="-0.135 0.0 0.009"/>
  </joint>
  <!--fb = front/back, lr = left/right-->
  <!--Defining Link-->
  <link name="front_left_wheel">
    <!--Visualization-->
    <visual>
      <geometry>
        <cylinder length="0.02" radius="0.04"/>
      </geometry>
      <!--origin-->
      <origin rpy="3.14159265359 0 0" xyz="0 0 0"/>
      <!--Material-->
      <material name="DarkGray"/>
    </visual>
    <!--Collision-->
    <collision>
      <!--Geometry-->
      <geometry>
        <cylinder length="0.02" radius="0.04"/>
      </geometry>
      <!--origin-->
      <origin rpy="3.14159265359 0 0" xyz="0 0 0"/>
    </collision>
    <!--Interial-->
    <cylinder_interia height="0.02" mass="2.5" radius="0.04"/>
  </link>
  <!--Defining Joint-->
  <joint name="front_left_wheel_joint" type="continuous">
    <!--Parent Link-->
    <parent link="base_link"/>
    <!--Child Link-->
    <child link="front_left_wheel"/>
    <!--Origin-->
    <origin rpy="0 0 0" xyz="0.0 -0.15 0.0"/>
    <!--Axis-->
    <axis rpy="0 0 0 " xyz="0 1 0"/>
    <!--Limit-->
    <limit effort="100" velocity="100"/>
    <!--Dynamics-->
    <dynamics damping="0" friction="0"/>
  </joint>
  <!--Defining Transmission-->
  <transmission name="front_left_wheel_joint_trans">
    <!--Defining type of transmission-->
    <type>transmission_interface/SimpleTransmission</type>
    <!--Transmisison joint-->
    <joint name="front_left_wheel_joint"/>
    <!--Defining Actuator-->
    <actuator name="front_left_wheel_joint_motor">
      <hardwareInterface>EffortJointInterface</hardwareInterface>
      <mechanicalReduction>1</mechanicalReduction>
    </actuator>
  </transmission>
  <!--fb = front/back, lr = left/right-->
  <!--Defining Link-->
  <link name="front_right_wheel">
    <!--Visualization-->
    <visual>
      <geometry>
        <cylinder length="0.02" radius="0.04"/>
      </geometry>
      <!--origin-->
      <origin rpy="3.14159265359 0 0" xyz="0 0 0"/>
      <!--Material-->
      <material name="DarkGray"/>
    </visual>
    <!--Collision-->
    <collision>
      <!--Geometry-->
      <geometry>
        <cylinder length="0.02" radius="0.04"/>
      </geometry>
      <!--origin-->
      <origin rpy="3.14159265359 0 0" xyz="0 0 0"/>
    </collision>
    <!--Interial-->
    <cylinder_interia height="0.02" mass="2.5" radius="0.04"/>
  </link>
  <!--Defining Joint-->
  <joint name="front_right_wheel_joint" type="continuous">
    <!--Parent Link-->
    <parent link="base_link"/>
    <!--Child Link-->
    <child link="front_right_wheel"/>
    <!--Origin-->
    <origin rpy="0 0 0" xyz="0.0 0.15 0.0"/>
    <!--Axis-->
    <axis rpy="0 0 0 " xyz="0 1 0"/>
    <!--Limit-->
    <limit effort="100" velocity="100"/>
    <!--Dynamics-->
    <dynamics damping="0" friction="0"/>
  </joint>
  <!--Defining Transmission-->
  <transmission name="front_right_wheel_joint_trans">
    <!--Defining type of transmission-->
    <type>transmission_interface/SimpleTransmission</type>
    <!--Transmisison joint-->
    <joint name="front_right_wheel_joint"/>
    <!--Defining Actuator-->
    <actuator name="front_right_wheel_joint_motor">
      <hardwareInterface>EffortJointInterface</hardwareInterface>
      <mechanicalReduction>1</mechanicalReduction>
    </actuator>
  </transmission>
  <!--////////////////////////////////// Defining Hokuyo Laser Scanner /////////////////////////////////-->
  <link name="hokuyo_link">
    <visual>
      <!--Defining Visual properties-->
      <geometry>
        <box size="0.05 0.05 0.05"/>
      </geometry>
      <!--Defining Origin-->
      <origin rpy="0 0 0" xyz="0 0 0"/>
      <!--Defining Material -->
      <material name="Blue"/>
    </visual>
  </link>
  <!--Defining Joint-->
  <joint name="hokuyo_joint" type="fixed">
    <!--Parent Link-->
    <parent link="base_link"/>
    <!--Child Link-->
    <child link="hokuyo_link"/>
    <!--Defining Origin-->
    <origin rpy="0 0 0" xyz="0.125 0 0.0325"/>
  </joint>
</robot>

